<mujoco model="smpl">
  <compiler coordinate="local"/>
  <default>
    <motor ctrlrange="-1 1" ctrllimited="true"/>
    <geom condim="1" friction="1.0 0.05 0.05" solimp=".9 .99 .003" solref=".015 1"/>
    <joint limited="true" solimplimit="0 .99 .01"/>
    <site size=".04" group="3"/>
    <default class="force-torque">
      <site type="box" size=".01 .01 .02" rgba="1 0 0 1"/>
    </default>
    <default class="touch">
      <site type="capsule" rgba="0 0 1 .3"/>
    </default>
  </default>

  <worldbody>
    <body name="Pelvis" pos="0 0 0">
      <freejoint name="Pelvis"/>
      <geom type="sphere" contype="1" conaffinity="1" density="2000" size="0.09" pos="0.0000 0.0000 0.0000"/>
      
      <body name="L_Hip" pos="-0.0068 0.0695 -0.0914">
        <joint name="L_Hip_x" type="hinge" pos="0 0 0" axis="1 0 0" actuatorfrcrange="-300 300" stiffness="500" damping="50" armature="0.02" range="-30 90"/>
        <joint name="L_Hip_y" type="hinge" pos="0 0 0" axis="0 1 0" actuatorfrcrange="-300 300" stiffness="500" damping="50" armature="0.02" range="-140 60"/>
        <joint name="L_Hip_z" type="hinge" pos="0 0 0" axis="0 0 1" actuatorfrcrange="-300 300" stiffness="500" damping="50" armature="0.02" range="-35 60"/>
        <geom type="capsule" contype="1" conaffinity="1" density="1500" fromto="-0.000315 0.002401 -0.026264 -0.00396 0.030184 -0.330176" size="0.055"/>
        
        <body name="L_Knee" pos="-0.0045 0.0343 -0.3752">
          <joint name="L_Knee_x" type="hinge" pos="0 0 0" axis="1 0 0" actuatorfrcrange="-200 200" stiffness="500" damping="50" armature="0.02" range="-30 30"/>
          <joint name="L_Knee_y" type="hinge" pos="0 0 0" axis="0 1 0" actuatorfrcrange="-200 200" stiffness="500" damping="50" armature="0.02" range="0 160"/>
          <joint name="L_Knee_z" type="hinge" pos="0 0 0" axis="0 0 1" actuatorfrcrange="-200 200" stiffness="500" damping="50" armature="0.02" range="-30 30"/>
          <geom type="capsule" contype="1" conaffinity="1" density="1250" fromto="-0.005244 -0.001632 -0.04776 -0.038456 -0.011968 -0.35024" size="0.05"/>
          
          <body name="L_Ankle" pos="-0.0437 -0.0136 -0.398">
            <joint name="L_Ankle_x" type="hinge" pos="0 0 0" axis="1 0 0" actuatorfrcrange="-100 100" stiffness="400" damping="40" armature="0.02" range="-30 30"/>
            <joint name="L_Ankle_y" type="hinge" pos="0 0 0" axis="0 1 0" actuatorfrcrange="-100 100" stiffness="400" damping="40" armature="0.02" range="-55 55"/>
            <joint name="L_Ankle_z" type="hinge" pos="0 0 0" axis="0 0 1" actuatorfrcrange="-100 100" stiffness="400" damping="40" armature="0.02" range="-40 40"/>
            <geom type="box" contype="1" conaffinity="1" density="1000" pos="0.0346 0.0024 -0.0279" size="0.08 0.045 0.025" quat="1.0000 0.0000 0.0000 0.0000"/>
            
            <body name="L_Toe" pos="0.1193 0.0124 -0.0258">
              <joint name="L_Toe_x" type="hinge" pos="0 0 0" axis="1 0 0" actuatorfrcrange="-75 75" stiffness="200" damping="20" armature="0.02" range="-30 30"/>
              <joint name="L_Toe_y" type="hinge" pos="0 0 0" axis="0 1 0" actuatorfrcrange="-75 75" stiffness="200" damping="20" armature="0.02" range="-60 60"/>
              <joint name="L_Toe_z" type="hinge" pos="0 0 0" axis="0 0 1" actuatorfrcrange="-75 75" stiffness="200" damping="20" armature="0.02" range="-30 30"/>
              <geom type="box" contype="1" conaffinity="1" density="1000" pos="0.0252 -0.01 -0.008" size="0.025 0.045 0.018" quat="1.0000 0.0000 0.0000 0.0000"/>
            </body>
          </body>
        </body>
      </body>

      <body name="R_Hip" pos="-0.0043 -0.0677 -0.0905">
        <joint name="R_Hip_x" type="hinge" pos="0 0 0" axis="1 0 0" actuatorfrcrange="-300 300" stiffness="500" damping="50" armature="0.02" range="-90 30"/>
        <joint name="R_Hip_y" type="hinge" pos="0 0 0" axis="0 1 0" actuatorfrcrange="-300 300" stiffness="500" damping="50" armature="0.02" range="-140 60"/>
        <joint name="R_Hip_z" type="hinge" pos="0 0 0" axis="0 0 1" actuatorfrcrange="-300 300" stiffness="500" damping="50" armature="0.02" range="-60 35"/>
        <geom type="capsule" contype="1" conaffinity="1" density="1500" fromto="-0.000623 -0.002681 -0.026782 -0.007832 -0.033704 -0.336688" size="0.055"/>
        
        <body name="R_Knee" pos="-0.0089 -0.0383 -0.3826">
          <joint name="R_Knee_x" type="hinge" pos="0 0 0" axis="1 0 0" actuatorfrcrange="-200 200" stiffness="500" damping="50" armature="0.02" range="-30 30"/>
          <joint name="R_Knee_y" type="hinge" pos="0 0 0" axis="0 1 0" actuatorfrcrange="-200 200" stiffness="500" damping="50" armature="0.02" range="0 160"/>
          <joint name="R_Knee_z" type="hinge" pos="0 0 0" axis="0 0 1" actuatorfrcrange="-200 200" stiffness="500" damping="50" armature="0.02" range="-30 30"/>
          <geom type="capsule" contype="1" conaffinity="1" density="1250" fromto="-0.005076 0.001896 -0.047808 -0.037224 0.013904 -0.350592" size="0.05"/>
          
          <body name="R_Ankle" pos="-0.0423 0.0158 -0.3984">
            <joint name="R_Ankle_x" type="hinge" pos="0 0 0" axis="1 0 0" actuatorfrcrange="-100 100" stiffness="400" damping="40" armature="0.02" range="-30 30"/>
            <joint name="R_Ankle_y" type="hinge" pos="0 0 0" axis="0 1 0" actuatorfrcrange="-100 100" stiffness="400" damping="40" armature="0.02" range="-55 55"/>
            <joint name="R_Ankle_z" type="hinge" pos="0 0 0" axis="0 0 1" actuatorfrcrange="-100 100" stiffness="400" damping="40" armature="0.02" range="-40 40"/>
            <geom type="box" contype="1" conaffinity="1" density="1000" pos="0.0346 -0.0024 -0.0279" size="0.08 0.045 0.025" quat="1.0000 0.0000 0.0000 0.0000"/>
            
            <body name="R_Toe" pos="0.1193 -0.0124 -0.0258">
              <joint name="R_Toe_x" type="hinge" pos="0 0 0" axis="1 0 0" actuatorfrcrange="-75 75" stiffness="200" damping="20" armature="0.02" range="-30 30"/>
              <joint name="R_Toe_y" type="hinge" pos="0 0 0" axis="0 1 0" actuatorfrcrange="-75 75" stiffness="200" damping="20" armature="0.02" range="-60 60"/>
              <joint name="R_Toe_z" type="hinge" pos="0 0 0" axis="0 0 1" actuatorfrcrange="-75 75" stiffness="200" damping="20" armature="0.02" range="-30 30"/>
              <geom type="box" contype="1" conaffinity="1" density="1000" pos="0.0252 0.01 -0.008" size="0.025 0.045 0.018" quat="1.0000 0.0000 0.0000 0.0000"/>
            </body>
          </body>
        </body>
      </body>

      <body name="Torso" pos="-0.0267 -0.0025 0.109">
        <joint name="Torso_x" type="hinge" pos="0 0 0" axis="1 0 0" actuatorfrcrange="-300 300" stiffness="1000" damping="100" armature="0.02" range="-60 60"/>
        <joint name="Torso_y" type="hinge" pos="0 0 0" axis="0 1 0" actuatorfrcrange="-300 300" stiffness="1000" damping="100" armature="0.02" range="-60 90"/>
        <joint name="Torso_z" type="hinge" pos="0 0 0" axis="0 0 1" actuatorfrcrange="-300 300" stiffness="1000" damping="100" armature="0.02" range="-50 50"/>
        <geom type="sphere" contype="1" conaffinity="1" density="2000" size="0.07" pos="0.00011 0.00055 0.01352"/>
                    
        <body name="Spine" pos="0.0011 0.0055 0.1352">
          <joint name="Spine_x" type="hinge" pos="0 0 0" axis="1 0 0" actuatorfrcrange="-200 200" stiffness="1000" damping="100" armature="0.02" range="-60 60"/>
          <joint name="Spine_y" type="hinge" pos="0 0 0" axis="0 1 0" actuatorfrcrange="-200 200" stiffness="1000" damping="100" armature="0.02" range="-60 90"/>
          <joint name="Spine_z" type="hinge" pos="0 0 0" axis="0 0 1" actuatorfrcrange="-200 200" stiffness="1000" damping="100" armature="0.02" range="-50 50"/>
          <geom type="sphere" contype="1" conaffinity="1" density="2000" size="0.075" pos="0.0000 0.0000 0.0000"/>
          
          <body name="Chest" pos="0.0254 0.0015 0.0529">
            <joint name="Chest_x" type="hinge" pos="0 0 0" axis="1 0 0" actuatorfrcrange="-150 150" stiffness="1000" damping="100" armature="0.02" range="-60 60"/>
            <joint name="Chest_y" type="hinge" pos="0 0 0" axis="0 1 0" actuatorfrcrange="-150 150" stiffness="1000" damping="100" armature="0.02" range="-60 90"/>
            <joint name="Chest_z" type="hinge" pos="0 0 0" axis="0 0 1" actuatorfrcrange="-150 150" stiffness="1000" damping="100" armature="0.02" range="-50 50"/>
            <geom type="sphere" contype="1" conaffinity="1" density="2000" size="0.11" pos="-0.008 0.0000 0.04"/>
            
            <body name="Neck" pos="-0.0429 -0.0028 0.2139">
              <joint name="Neck_x" type="hinge" pos="0 0 0" axis="1 0 0" actuatorfrcrange="-75 75" stiffness="500" damping="50" armature="0.02" range="-50 50"/>
              <joint name="Neck_y" type="hinge" pos="0 0 0" axis="0 1 0" actuatorfrcrange="-75 75" stiffness="500" damping="50" armature="0.02" range="-40 60"/>
              <joint name="Neck_z" type="hinge" pos="0 0 0" axis="0 0 1" actuatorfrcrange="-75 75" stiffness="500" damping="50" armature="0.02" range="-45 45"/>
              <geom type="sphere" contype="1" conaffinity="1" density="1000" size="0.045" pos="0.02 0.0 0.0"/>
            
              <body name="Head" pos="0.0513 0.0052 0.065">
                <joint name="Head_x" type="hinge" pos="0 0 0" axis="1 0 0" actuatorfrcrange="-25 25" stiffness="200" damping="20" armature="0.02" range="-50 50"/>
                <joint name="Head_y" type="hinge" pos="0 0 0" axis="0 1 0" actuatorfrcrange="-25 25" stiffness="200" damping="20" armature="0.02" range="-40 60"/>
                <joint name="Head_z" type="hinge" pos="0 0 0" axis="0 0 1" actuatorfrcrange="-25 25" stiffness="200" damping="20" armature="0.02" range="-45 45"/>
                <geom type="sphere" contype="1" conaffinity="1" density="1000" size="0.095" pos="0.0000 0.0000 0.0000"/>
              </body>
            </body>
            
            <body name="L_Thorax" pos="-0.0341 0.0788 0.1217">
              <joint name="L_Thorax_x" type="hinge" pos="0 0 0" axis="1 0 0" actuatorfrcrange="-200 200" stiffness="500" damping="50" armature="0.02" range="-40 30"/>
              <joint name="L_Thorax_y" type="hinge" pos="0 0 0" axis="0 1 0" actuatorfrcrange="-200 200" stiffness="500" damping="50" armature="0.02" range="-30 30"/>
              <joint name="L_Thorax_z" type="hinge" pos="0 0 0" axis="0 0 1" actuatorfrcrange="-200 200" stiffness="500" damping="50" armature="0.02" range="-30 30"/>
              <geom type="sphere" contype="1" conaffinity="1" density="1000" size="0.055" pos="-0.00445 0.0455 0.01525"/>
            
              <body name="L_Shoulder" pos="-0.0089 0.091 0.0305">
                <joint name="L_Shoulder_x" type="hinge" pos="0 0 0" axis="1 0 0" actuatorfrcrange="-150 150" stiffness="400" damping="40" armature="0.02" range="-135 90"/>
                <joint name="L_Shoulder_y" type="hinge" pos="0 0 0" axis="0 1 0" actuatorfrcrange="-150 150" stiffness="400" damping="40" armature="0.02" range="-90 90"/>
                <joint name="L_Shoulder_z" type="hinge" pos="0 0 0" axis="0 0 1" actuatorfrcrange="-150 150" stiffness="400" damping="40" armature="0.02" range="-160 60"/>
                <geom type="capsule" contype="1" conaffinity="1" density="1000" fromto="-0.0055 0.05192 -0.00256 -0.023375 0.22066 -0.01088" size="0.045"/>
                
                <body name="L_Elbow" pos="-0.0275 0.2596 -0.0128">
                  <joint name="L_Elbow_x" type="hinge" pos="0 0 0" axis="1 0 0" actuatorfrcrange="-100 100" stiffness="300" damping="30" armature="0.02" range="-30 30"/>
                  <joint name="L_Elbow_y" type="hinge" pos="0 0 0" axis="0 1 0" actuatorfrcrange="-100 100" stiffness="300" damping="30" armature="0.02" range="-30 30"/>
                  <joint name="L_Elbow_z" type="hinge" pos="0 0 0" axis="0 0 1" actuatorfrcrange="-100 100" stiffness="300" damping="30" armature="0.02" range="-160 0"/>
                  <geom type="capsule" contype="1" conaffinity="1" density="1000" fromto="-0.00018 0.03738 0.00135 -0.0009 0.1994 0.0072" size="0.04"/>
                  
                  <body name="L_Wrist" pos="-0.0012 0.2492 0.009">
                    <joint name="L_Wrist_x" type="hinge" pos="0 0 0" axis="1 0 0" actuatorfrcrange="-75 75" stiffness="200" damping="20" armature="0.02" range="-90 90"/>
                    <joint name="L_Wrist_y" type="hinge" pos="0 0 0" axis="0 1 0" actuatorfrcrange="-75 75" stiffness="200" damping="20" armature="0.02" range="-90 90"/>
                    <joint name="L_Wrist_z" type="hinge" pos="0 0 0" axis="0 0 1" actuatorfrcrange="-75 75" stiffness="200" damping="20" armature="0.02" range="-60 60"/>
                    <geom type="capsule" contype="1" conaffinity="1" density="1000" fromto="-0.0030 0.0168 -0.0016 -0.0120 0.0672 -0.0065" size="0.0318"/>
                    
                    <body name="L_Hand" pos="-0.0149 0.084 -0.0082">
                      <joint name="L_Hand_x" type="hinge" pos="0 0 0" axis="1 0 0" actuatorfrcrange="-50 50" stiffness="100" damping="10" armature="0.02" range="-90 90"/>
                      <joint name="L_Hand_y" type="hinge" pos="0 0 0" axis="0 1 0" actuatorfrcrange="-50 50" stiffness="100" damping="10" armature="0.02" range="-90 90"/>
                      <joint name="L_Hand_z" type="hinge" pos="0 0 0" axis="0 0 1" actuatorfrcrange="-50 50" stiffness="100" damping="10" armature="0.02" range="-90 90"/>
                      <geom type="sphere" contype="1" conaffinity="1" density="1000" size="0.0337" pos="0.0000 0.0000 0.0000"/>
                    </body>
                  </body>
                </body>
              </body>
            </body>

            <body name="R_Thorax" pos="-0.0386 -0.0818 0.1188">
              <joint name="R_Thorax_x" type="hinge" pos="0 0 0" axis="1 0 0" actuatorfrcrange="-200 200" stiffness="500" damping="50" armature="0.02" range="-30 40"/>
              <joint name="R_Thorax_y" type="hinge" pos="0 0 0" axis="0 1 0" actuatorfrcrange="-200 200" stiffness="500" damping="50" armature="0.02" range="-30 30"/>
              <joint name="R_Thorax_z" type="hinge" pos="0 0 0" axis="0 0 1" actuatorfrcrange="-200 200" stiffness="500" damping="50" armature="0.02" range="-30 30"/>
              <geom type="sphere" contype="1" conaffinity="1" density="1000" size="0.055" pos="-0.00455 -0.048 0.0163"/>
            
              <body name="R_Shoulder" pos="-0.0091 -0.096 0.0326">
                <joint name="R_Shoulder_x" type="hinge" pos="0 0 0" axis="1 0 0" actuatorfrcrange="-150 150" stiffness="400" damping="40" armature="0.02" range="-90 135"/>
                <joint name="R_Shoulder_y" type="hinge" pos="0 0 0" axis="0 1 0" actuatorfrcrange="-150 150" stiffness="400" damping="40" armature="0.02" range="-90 90"/>
                <joint name="R_Shoulder_z" type="hinge" pos="0 0 0" axis="0 0 1" actuatorfrcrange="-150 150" stiffness="400" damping="40" armature="0.02" range="-60 160"/>
                <geom type="capsule" contype="1" conaffinity="1" density="1000" fromto="-0.00428 -0.05074 -0.00266 -0.01819 -0.215645 -0.011305" size="0.045"/>
                
                <body name="R_Elbow" pos="-0.0214 -0.2537 -0.0133">
                  <joint name="R_Elbow_x" type="hinge" pos="0 0 0" axis="1 0 0" actuatorfrcrange="-100 100" stiffness="300" damping="30" armature="0.02" range="-30 30"/>
                  <joint name="R_Elbow_y" type="hinge" pos="0 0 0" axis="0 1 0" actuatorfrcrange="-100 100" stiffness="300" damping="30" armature="0.02" range="-30 30"/>
                  <joint name="R_Elbow_z" type="hinge" pos="0 0 0" axis="0 0 1" actuatorfrcrange="-100 100" stiffness="300" damping="30" armature="0.02" range="0 160"/>
                  <geom type="capsule" contype="1" conaffinity="1" density="1000" fromto="-0.00084 -0.038295 0.00117 -0.00448 -0.20424 0.00624" size="0.04"/>
                  
                  <body name="R_Wrist" pos="-0.0056 -0.2553 0.0078">
                    <joint name="R_Wrist_x" type="hinge" pos="0 0 0" axis="1 0 0" actuatorfrcrange="-75 75" stiffness="200" damping="20" armature="0.02" range="-90 90"/>
                    <joint name="R_Wrist_y" type="hinge" pos="0 0 0" axis="0 1 0" actuatorfrcrange="-75 75" stiffness="200" damping="20" armature="0.02" range="-90 90"/>
                    <joint name="R_Wrist_z" type="hinge" pos="0 0 0" axis="0 0 1" actuatorfrcrange="-75 75" stiffness="200" damping="20" armature="0.02" range="-60 60"/>
                    <geom type="capsule" contype="1" conaffinity="1" density="1000" fromto="-0.0021 -0.0169 -0.0012 -0.0083 -0.0677 -0.0049" size="0.0326"/>
                    
                    <body name="R_Hand" pos="-0.0103 -0.0846 -0.0061">
                      <joint name="R_Hand_x" type="hinge" pos="0 0 0" axis="1 0 0" actuatorfrcrange="-50 50" stiffness="100" damping="10" armature="0.02" range="-90 90"/>
                      <joint name="R_Hand_y" type="hinge" pos="0 0 0" axis="0 1 0" actuatorfrcrange="-50 50" stiffness="100" damping="10" armature="0.02" range="-90 90"/>
                      <joint name="R_Hand_z" type="hinge" pos="0 0 0" axis="0 0 1" actuatorfrcrange="-50 50" stiffness="100" damping="10" armature="0.02" range="-90 90"/>
                      <geom type="sphere" contype="1" conaffinity="1" density="1000" size="0.0340" pos="0.0000 0.0000 0.0000"/>
                    </body>
                  </body>
                </body>
              </body>
            </body>
          </body>
        </body>
      </body>
    </body>
  </worldbody>

  <actuator>
    <motor name="L_Hip_x" joint="L_Hip_x" gear="300"/>
    <motor name="L_Hip_y" joint="L_Hip_y" gear="300"/>
    <motor name="L_Hip_z" joint="L_Hip_z" gear="300"/>
    <motor name="L_Knee_x" joint="L_Knee_x" gear="200"/>
    <motor name="L_Knee_y" joint="L_Knee_y" gear="200"/>
    <motor name="L_Knee_z" joint="L_Knee_z" gear="200"/>
    <motor name="L_Ankle_x" joint="L_Ankle_x" gear="100"/>
    <motor name="L_Ankle_y" joint="L_Ankle_y" gear="100"/>
    <motor name="L_Ankle_z" joint="L_Ankle_z" gear="100"/>
    <motor name="L_Toe_x" joint="L_Toe_x" gear="75"/>
    <motor name="L_Toe_y" joint="L_Toe_y" gear="75"/>
    <motor name="L_Toe_z" joint="L_Toe_z" gear="75"/>
    <motor name="R_Hip_x" joint="R_Hip_x" gear="300"/>
    <motor name="R_Hip_y" joint="R_Hip_y" gear="300"/>
    <motor name="R_Hip_z" joint="R_Hip_z" gear="300"/>
    <motor name="R_Knee_x" joint="R_Knee_x" gear="200"/>
    <motor name="R_Knee_y" joint="R_Knee_y" gear="200"/>
    <motor name="R_Knee_z" joint="R_Knee_z" gear="200"/>
    <motor name="R_Ankle_x" joint="R_Ankle_x" gear="100"/>
    <motor name="R_Ankle_y" joint="R_Ankle_y" gear="100"/>
    <motor name="R_Ankle_z" joint="R_Ankle_z" gear="100"/>
    <motor name="R_Toe_x" joint="R_Toe_x" gear="75"/>
    <motor name="R_Toe_y" joint="R_Toe_y" gear="75"/>
    <motor name="R_Toe_z" joint="R_Toe_z" gear="75"/>
    <motor name="Torso_x" joint="Torso_x" gear="300"/>
    <motor name="Torso_y" joint="Torso_y" gear="300"/>
    <motor name="Torso_z" joint="Torso_z" gear="300"/>
    <motor name="Spine_x" joint="Spine_x" gear="200"/>
    <motor name="Spine_y" joint="Spine_y" gear="200"/>
    <motor name="Spine_z" joint="Spine_z" gear="200"/>
    <motor name="Chest_x" joint="Chest_x" gear="150"/>
    <motor name="Chest_y" joint="Chest_y" gear="150"/>
    <motor name="Chest_z" joint="Chest_z" gear="150"/>
    <motor name="Neck_x" joint="Neck_x" gear="75"/>
    <motor name="Neck_y" joint="Neck_y" gear="75"/>
    <motor name="Neck_z" joint="Neck_z" gear="75"/>
    <motor name="Head_x" joint="Head_x" gear="25"/>
    <motor name="Head_y" joint="Head_y" gear="25"/>
    <motor name="Head_z" joint="Head_z" gear="25"/>
    <motor name="L_Thorax_x" joint="L_Thorax_x" gear="200"/>
    <motor name="L_Thorax_y" joint="L_Thorax_y" gear="200"/>
    <motor name="L_Thorax_z" joint="L_Thorax_z" gear="200"/>
    <motor name="L_Shoulder_x" joint="L_Shoulder_x" gear="150"/>
    <motor name="L_Shoulder_y" joint="L_Shoulder_y" gear="150"/>
    <motor name="L_Shoulder_z" joint="L_Shoulder_z" gear="150"/>
    <motor name="L_Elbow_x" joint="L_Elbow_x" gear="100"/>
    <motor name="L_Elbow_y" joint="L_Elbow_y" gear="100"/>
    <motor name="L_Elbow_z" joint="L_Elbow_z" gear="100"/>
    <motor name="L_Wrist_x" joint="L_Wrist_x" gear="75"/>
    <motor name="L_Wrist_y" joint="L_Wrist_y" gear="75"/>
    <motor name="L_Wrist_z" joint="L_Wrist_z" gear="75"/>
    <motor name="L_Hand_x" joint="L_Hand_x" gear="50"/>
    <motor name="L_Hand_y" joint="L_Hand_y" gear="50"/>
    <motor name="L_Hand_z" joint="L_Hand_z" gear="50"/>
    <motor name="R_Thorax_x" joint="R_Thorax_x" gear="200"/>
    <motor name="R_Thorax_y" joint="R_Thorax_y" gear="200"/>
    <motor name="R_Thorax_z" joint="R_Thorax_z" gear="200"/>
    <motor name="R_Shoulder_x" joint="R_Shoulder_x" gear="150"/>
    <motor name="R_Shoulder_y" joint="R_Shoulder_y" gear="150"/>
    <motor name="R_Shoulder_z" joint="R_Shoulder_z" gear="150"/>
    <motor name="R_Elbow_x" joint="R_Elbow_x" gear="100"/>
    <motor name="R_Elbow_y" joint="R_Elbow_y" gear="100"/>
    <motor name="R_Elbow_z" joint="R_Elbow_z" gear="100"/>
    <motor name="R_Wrist_x" joint="R_Wrist_x" gear="75"/>
    <motor name="R_Wrist_y" joint="R_Wrist_y" gear="75"/>
    <motor name="R_Wrist_z" joint="R_Wrist_z" gear="75"/>
    <motor name="R_Hand_x" joint="R_Hand_x" gear="50"/>
    <motor name="R_Hand_y" joint="R_Hand_y" gear="50"/>
    <motor name="R_Hand_z" joint="R_Hand_z" gear="50"/>
  </actuator>
</mujoco>
